[2020-02-04 21:21:50 +0800] [29442] [DEBUG] Current configuration:
  config: gunicorn_config_dev.py
  bind: ['0.0.0.0:8080']
  backlog: 2048
  workers: 12
  worker_class: sync
  threads: 1
  worker_connections: 1000
  max_requests: 0
  max_requests_jitter: 0
  timeout: 30
  graceful_timeout: 30
  keepalive: 2
  limit_request_line: 4094
  limit_request_fields: 100
  limit_request_field_size: 8190
  reload: False
  reload_engine: auto
  reload_extra_files: []
  spew: False
  check_config: False
  preload_app: False
  sendfile: None
  reuse_port: False
  chdir: /home/qiongwei/mycode/pythonenv/virtualenv/pingpongus
  daemon: False
  raw_env: []
  pidfile: /home/qiongwei/mycode/pythonenv/virtualenv/pingpongus/app/log/gunicorn.pid
  worker_tmp_dir: None
  user: 1000
  group: 1000
  umask: 0
  initgroups: False
  tmp_upload_dir: None
  secure_scheme_headers: {'X-FORWARDED-PROTOCOL': 'ssl', 'X-FORWARDED-PROTO': 'https', 'X-FORWARDED-SSL': 'on'}
  forwarded_allow_ips: ['127.0.0.1']
  accesslog: /home/qiongwei/mycode/pythonenv/virtualenv/pingpongus/app/log/access.log
  disable_redirect_access_to_syslog: False
  access_log_format: %(h)s %(l)s %(u)s %(t)s "%(r)s" %(s)s %(b)s "%(f)s" "%(a)s"
  errorlog: /home/qiongwei/mycode/pythonenv/virtualenv/pingpongus/app/log/debug.log
  loglevel: debug
  capture_output: False
  logger_class: gunicorn.glogging.Logger
  logconfig: None
  logconfig_dict: {}
  syslog_addr: udp://localhost:514
  syslog: False
  syslog_prefix: None
  syslog_facility: user
  enable_stdio_inheritance: False
  statsd_host: None
  dogstatsd_tags: 
  statsd_prefix: 
  proc_name: None
  default_proc_name: run:app
  pythonpath: None
  paste: None
  on_starting: <function OnStarting.on_starting at 0x7f4664ecc440>
  on_reload: <function OnReload.on_reload at 0x7f4664ecc560>
  when_ready: <function WhenReady.when_ready at 0x7f4664ecc680>
  pre_fork: <function Prefork.pre_fork at 0x7f4664ecc7a0>
  post_fork: <function Postfork.post_fork at 0x7f4664ecc8c0>
  post_worker_init: <function PostWorkerInit.post_worker_init at 0x7f4664ecc9e0>
  worker_int: <function WorkerInt.worker_int at 0x7f4664eccb00>
  worker_abort: <function WorkerAbort.worker_abort at 0x7f4664eccc20>
  pre_exec: <function PreExec.pre_exec at 0x7f4664eccd40>
  pre_request: <function PreRequest.pre_request at 0x7f4664ecce60>
  post_request: <function PostRequest.post_request at 0x7f4664eccef0>
  child_exit: <function ChildExit.child_exit at 0x7f4664d9b050>
  worker_exit: <function WorkerExit.worker_exit at 0x7f4664d9b170>
  nworkers_changed: <function NumWorkersChanged.nworkers_changed at 0x7f4664d9b290>
  on_exit: <function OnExit.on_exit at 0x7f4664d9b3b0>
  proxy_protocol: False
  proxy_allow_ips: ['127.0.0.1']
  keyfile: None
  certfile: None
  ssl_version: 2
  cert_reqs: 0
  ca_certs: None
  suppress_ragged_eofs: True
  do_handshake_on_connect: False
  ciphers: None
  raw_paste_global_conf: []
  strip_header_spaces: False
[2020-02-04 21:21:50 +0800] [29442] [INFO] Starting gunicorn 20.0.4
[2020-02-04 21:21:50 +0800] [29442] [DEBUG] Arbiter booted
[2020-02-04 21:21:50 +0800] [29442] [INFO] Listening at: http://0.0.0.0:8080 (29442)
[2020-02-04 21:21:50 +0800] [29442] [INFO] Using worker: sync
[2020-02-04 21:21:50 +0800] [29447] [INFO] Booting worker with pid: 29447
[2020-02-04 21:21:50 +0800] [29448] [INFO] Booting worker with pid: 29448
[2020-02-04 21:21:50 +0800] [29449] [INFO] Booting worker with pid: 29449
[2020-02-04 21:21:50 +0800] [29450] [INFO] Booting worker with pid: 29450
[2020-02-04 21:21:50 +0800] [29451] [INFO] Booting worker with pid: 29451
[2020-02-04 21:21:50 +0800] [29452] [INFO] Booting worker with pid: 29452
[2020-02-04 21:21:50 +0800] [29453] [INFO] Booting worker with pid: 29453
[2020-02-04 21:21:50 +0800] [29456] [INFO] Booting worker with pid: 29456
[2020-02-04 21:21:50 +0800] [29457] [INFO] Booting worker with pid: 29457
[2020-02-04 21:21:50 +0800] [29458] [INFO] Booting worker with pid: 29458
[2020-02-04 21:21:50 +0800] [29459] [INFO] Booting worker with pid: 29459
[2020-02-04 21:21:50 +0800] [29460] [INFO] Booting worker with pid: 29460
[2020-02-04 21:21:50 +0800] [29442] [DEBUG] 12 workers
[2020-02-04 21:21:52 +0800] [29451] [DEBUG] GET /h5snake
[2020-02-04 21:26:00 +0800] [29453] [DEBUG] GET /h5snake
[2020-02-04 22:50:22 +0800] [29451] [DEBUG] GET /h5snake
[2020-02-04 22:58:18 +0800] [29447] [DEBUG] GET /h5snake
[2020-02-04 23:00:16 +0800] [29459] [DEBUG] GET /h5snake
[2020-02-04 23:01:59 +0800] [29451] [DEBUG] GET /h5snake
[2020-02-04 23:28:17 +0800] [29452] [DEBUG] GET /h5snake
[2020-02-04 23:30:06 +0800] [29453] [DEBUG] GET /h5snake
[2020-02-04 23:32:29 +0800] [29450] [DEBUG] GET /h5snake
[2020-02-04 23:36:55 +0800] [29451] [DEBUG] GET /h5snake
[2020-02-05 14:34:56 +0800] [29442] [CRITICAL] WORKER TIMEOUT (pid:29447)
[2020-02-05 14:34:56 +0800] [29442] [CRITICAL] WORKER TIMEOUT (pid:29448)
[2020-02-05 14:34:56 +0800] [29442] [CRITICAL] WORKER TIMEOUT (pid:29449)
[2020-02-05 14:34:56 +0800] [29442] [CRITICAL] WORKER TIMEOUT (pid:29450)
[2020-02-05 14:34:56 +0800] [29447] [INFO] Worker exiting (pid: 29447)
[2020-02-05 14:34:56 +0800] [29442] [CRITICAL] WORKER TIMEOUT (pid:29451)
[2020-02-05 14:34:56 +0800] [29442] [CRITICAL] WORKER TIMEOUT (pid:29452)
[2020-02-05 14:34:56 +0800] [29448] [INFO] Worker exiting (pid: 29448)
[2020-02-05 14:34:56 +0800] [29442] [CRITICAL] WORKER TIMEOUT (pid:29453)
[2020-02-05 14:34:56 +0800] [29450] [INFO] Worker exiting (pid: 29450)
[2020-02-05 14:34:56 +0800] [29449] [INFO] Worker exiting (pid: 29449)
[2020-02-05 14:34:56 +0800] [29442] [CRITICAL] WORKER TIMEOUT (pid:29456)
[2020-02-05 14:34:56 +0800] [29451] [INFO] Worker exiting (pid: 29451)
[2020-02-05 14:34:56 +0800] [29452] [INFO] Worker exiting (pid: 29452)
[2020-02-05 14:34:56 +0800] [29453] [INFO] Worker exiting (pid: 29453)
[2020-02-05 14:34:56 +0800] [29456] [INFO] Worker exiting (pid: 29456)
[2020-02-05 14:34:56 +0800] [29442] [CRITICAL] WORKER TIMEOUT (pid:29457)
[2020-02-05 14:34:56 +0800] [29457] [INFO] Worker exiting (pid: 29457)
[2020-02-05 14:34:56 +0800] [29442] [CRITICAL] WORKER TIMEOUT (pid:29458)
[2020-02-05 14:34:56 +0800] [29442] [CRITICAL] WORKER TIMEOUT (pid:29459)
[2020-02-05 14:34:56 +0800] [29442] [CRITICAL] WORKER TIMEOUT (pid:29460)
[2020-02-05 14:34:56 +0800] [29458] [INFO] Worker exiting (pid: 29458)
[2020-02-05 14:34:56 +0800] [29459] [INFO] Worker exiting (pid: 29459)
[2020-02-05 14:34:56 +0800] [29460] [INFO] Worker exiting (pid: 29460)
[2020-02-05 14:34:56 +0800] [1677] [INFO] Booting worker with pid: 1677
[2020-02-05 14:34:56 +0800] [1679] [INFO] Booting worker with pid: 1679
[2020-02-05 14:34:57 +0800] [29442] [DEBUG] 2 workers
[2020-02-05 14:34:57 +0800] [1680] [INFO] Booting worker with pid: 1680
[2020-02-05 14:34:57 +0800] [1681] [INFO] Booting worker with pid: 1681
[2020-02-05 14:34:57 +0800] [1677] [ERROR] Exception in worker process
Traceback (most recent call last):
  File "/home/qiongwei/mycode/pythonenv/virtualenv/lib/python3.7/site-packages/pymysql/connections.py", line 583, in connect
    **kwargs)
  File "/usr/lib64/python3.7/socket.py", line 727, in create_connection
    raise err
  File "/usr/lib64/python3.7/socket.py", line 716, in create_connection
    sock.connect(sa)
OSError: [Errno 101] Network is unreachable

During handling of the above exception, another exception occurred:

Traceback (most recent call last):
  File "/home/qiongwei/mycode/pythonenv/virtualenv/lib/python3.7/site-packages/gunicorn/arbiter.py", line 583, in spawn_worker
    worker.init_process()
  File "/home/qiongwei/mycode/pythonenv/virtualenv/lib/python3.7/site-packages/gunicorn/workers/base.py", line 119, in init_process
    self.load_wsgi()
  File "/home/qiongwei/mycode/pythonenv/virtualenv/lib/python3.7/site-packages/gunicorn/workers/base.py", line 144, in load_wsgi
    self.wsgi = self.app.wsgi()
  File "/home/qiongwei/mycode/pythonenv/virtualenv/lib/python3.7/site-packages/gunicorn/app/base.py", line 67, in wsgi
    self.callable = self.load()
  File "/home/qiongwei/mycode/pythonenv/virtualenv/lib/python3.7/site-packages/gunicorn/app/wsgiapp.py", line 49, in load
    return self.load_wsgiapp()
  File "/home/qiongwei/mycode/pythonenv/virtualenv/lib/python3.7/site-packages/gunicorn/app/wsgiapp.py", line 39, in load_wsgiapp
    return util.import_app(self.app_uri)
  File "/home/qiongwei/mycode/pythonenv/virtualenv/lib/python3.7/site-packages/gunicorn/util.py", line 358, in import_app
    mod = importlib.import_module(module)
  File "/home/qiongwei/mycode/pythonenv/virtualenv/lib/python3.7/importlib/__init__.py", line 127, in import_module
    return _bootstrap._gcd_import(name[level:], package, level)
  File "<frozen importlib._bootstrap>", line 1006, in _gcd_import
  File "<frozen importlib._bootstrap>", line 983, in _find_and_load
  File "<frozen importlib._bootstrap>", line 967, in _find_and_load_unlocked
  File "<frozen importlib._bootstrap>", line 677, in _load_unlocked
  File "<frozen importlib._bootstrap_external>", line 728, in exec_module
  File "<frozen importlib._bootstrap>", line 219, in _call_with_frames_removed
  File "/home/qiongwei/mycode/pythonenv/virtualenv/pingpongus/run.py", line 21, in <module>
    charset='utf8'
  File "/home/qiongwei/mycode/pythonenv/virtualenv/lib/python3.7/site-packages/pymysql/__init__.py", line 94, in Connect
    return Connection(*args, **kwargs)
  File "/home/qiongwei/mycode/pythonenv/virtualenv/lib/python3.7/site-packages/pymysql/connections.py", line 325, in __init__
    self.connect()
  File "/home/qiongwei/mycode/pythonenv/virtualenv/lib/python3.7/site-packages/pymysql/connections.py", line 630, in connect
    raise exc
pymysql.err.OperationalError: (2003, "Can't connect to MySQL server on '47.112.159.211' ([Errno 101] Network is unreachable)")
[2020-02-05 14:34:57 +0800] [1677] [INFO] Worker exiting (pid: 1677)
[2020-02-05 14:34:57 +0800] [1682] [INFO] Booting worker with pid: 1682
[2020-02-05 14:34:57 +0800] [1679] [ERROR] Exception in worker process
Traceback (most recent call last):
  File "/home/qiongwei/mycode/pythonenv/virtualenv/lib/python3.7/site-packages/pymysql/connections.py", line 583, in connect
    **kwargs)
  File "/usr/lib64/python3.7/socket.py", line 727, in create_connection
    raise err
  File "/usr/lib64/python3.7/socket.py", line 716, in create_connection
    sock.connect(sa)
OSError: [Errno 101] Network is unreachable

During handling of the above exception, another exception occurred:

Traceback (most recent call last):
  File "/home/qiongwei/mycode/pythonenv/virtualenv/lib/python3.7/site-packages/gunicorn/arbiter.py", line 583, in spawn_worker
    worker.init_process()
  File "/home/qiongwei/mycode/pythonenv/virtualenv/lib/python3.7/site-packages/gunicorn/workers/base.py", line 119, in init_process
    self.load_wsgi()
  File "/home/qiongwei/mycode/pythonenv/virtualenv/lib/python3.7/site-packages/gunicorn/workers/base.py", line 144, in load_wsgi
    self.wsgi = self.app.wsgi()
  File "/home/qiongwei/mycode/pythonenv/virtualenv/lib/python3.7/site-packages/gunicorn/app/base.py", line 67, in wsgi
    self.callable = self.load()
  File "/home/qiongwei/mycode/pythonenv/virtualenv/lib/python3.7/site-packages/gunicorn/app/wsgiapp.py", line 49, in load
    return self.load_wsgiapp()
  File "/home/qiongwei/mycode/pythonenv/virtualenv/lib/python3.7/site-packages/gunicorn/app/wsgiapp.py", line 39, in load_wsgiapp
    return util.import_app(self.app_uri)
  File "/home/qiongwei/mycode/pythonenv/virtualenv/lib/python3.7/site-packages/gunicorn/util.py", line 358, in import_app
    mod = importlib.import_module(module)
  File "/home/qiongwei/mycode/pythonenv/virtualenv/lib/python3.7/importlib/__init__.py", line 127, in import_module
    return _bootstrap._gcd_import(name[level:], package, level)
  File "<frozen importlib._bootstrap>", line 1006, in _gcd_import
  File "<frozen importlib._bootstrap>", line 983, in _find_and_load
  File "<frozen importlib._bootstrap>", line 967, in _find_and_load_unlocked
  File "<frozen importlib._bootstrap>", line 677, in _load_unlocked
  File "<frozen importlib._bootstrap_external>", line 728, in exec_module
  File "<frozen importlib._bootstrap>", line 219, in _call_with_frames_removed
  File "/home/qiongwei/mycode/pythonenv/virtualenv/pingpongus/run.py", line 21, in <module>
    charset='utf8'
  File "/home/qiongwei/mycode/pythonenv/virtualenv/lib/python3.7/site-packages/pymysql/__init__.py", line 94, in Connect
    return Connection(*args, **kwargs)
  File "/home/qiongwei/mycode/pythonenv/virtualenv/lib/python3.7/site-packages/pymysql/connections.py", line 325, in __init__
    self.connect()
  File "/home/qiongwei/mycode/pythonenv/virtualenv/lib/python3.7/site-packages/pymysql/connections.py", line 630, in connect
    raise exc
pymysql.err.OperationalError: (2003, "Can't connect to MySQL server on '47.112.159.211' ([Errno 101] Network is unreachable)")
[2020-02-05 14:34:57 +0800] [1679] [INFO] Worker exiting (pid: 1679)
[2020-02-05 14:34:57 +0800] [1680] [ERROR] Exception in worker process
Traceback (most recent call last):
  File "/home/qiongwei/mycode/pythonenv/virtualenv/lib/python3.7/site-packages/pymysql/connections.py", line 583, in connect
    **kwargs)
  File "/usr/lib64/python3.7/socket.py", line 727, in create_connection
    raise err
  File "/usr/lib64/python3.7/socket.py", line 716, in create_connection
    sock.connect(sa)
OSError: [Errno 101] Network is unreachable

During handling of the above exception, another exception occurred:

Traceback (most recent call last):
  File "/home/qiongwei/mycode/pythonenv/virtualenv/lib/python3.7/site-packages/gunicorn/arbiter.py", line 583, in spawn_worker
    worker.init_process()
  File "/home/qiongwei/mycode/pythonenv/virtualenv/lib/python3.7/site-packages/gunicorn/workers/base.py", line 119, in init_process
    self.load_wsgi()
  File "/home/qiongwei/mycode/pythonenv/virtualenv/lib/python3.7/site-packages/gunicorn/workers/base.py", line 144, in load_wsgi
    self.wsgi = self.app.wsgi()
  File "/home/qiongwei/mycode/pythonenv/virtualenv/lib/python3.7/site-packages/gunicorn/app/base.py", line 67, in wsgi
    self.callable = self.load()
  File "/home/qiongwei/mycode/pythonenv/virtualenv/lib/python3.7/site-packages/gunicorn/app/wsgiapp.py", line 49, in load
    return self.load_wsgiapp()
  File "/home/qiongwei/mycode/pythonenv/virtualenv/lib/python3.7/site-packages/gunicorn/app/wsgiapp.py", line 39, in load_wsgiapp
    return util.import_app(self.app_uri)
  File "/home/qiongwei/mycode/pythonenv/virtualenv/lib/python3.7/site-packages/gunicorn/util.py", line 358, in import_app
    mod = importlib.import_module(module)
  File "/home/qiongwei/mycode/pythonenv/virtualenv/lib/python3.7/importlib/__init__.py", line 127, in import_module
    return _bootstrap._gcd_import(name[level:], package, level)
  File "<frozen importlib._bootstrap>", line 1006, in _gcd_import
  File "<frozen importlib._bootstrap>", line 983, in _find_and_load
  File "<frozen importlib._bootstrap>", line 967, in _find_and_load_unlocked
  File "<frozen importlib._bootstrap>", line 677, in _load_unlocked
  File "<frozen importlib._bootstrap_external>", line 728, in exec_module
  File "<frozen importlib._bootstrap>", line 219, in _call_with_frames_removed
  File "/home/qiongwei/mycode/pythonenv/virtualenv/pingpongus/run.py", line 21, in <module>
    charset='utf8'
  File "/home/qiongwei/mycode/pythonenv/virtualenv/lib/python3.7/site-packages/pymysql/__init__.py", line 94, in Connect
    return Connection(*args, **kwargs)
  File "/home/qiongwei/mycode/pythonenv/virtualenv/lib/python3.7/site-packages/pymysql/connections.py", line 325, in __init__
    self.connect()
  File "/home/qiongwei/mycode/pythonenv/virtualenv/lib/python3.7/site-packages/pymysql/connections.py", line 630, in connect
    raise exc
pymysql.err.OperationalError: (2003, "Can't connect to MySQL server on '47.112.159.211' ([Errno 101] Network is unreachable)")
[2020-02-05 14:34:57 +0800] [1680] [INFO] Worker exiting (pid: 1680)
[2020-02-05 14:34:57 +0800] [1681] [ERROR] Exception in worker process
Traceback (most recent call last):
  File "/home/qiongwei/mycode/pythonenv/virtualenv/lib/python3.7/site-packages/pymysql/connections.py", line 583, in connect
    **kwargs)
  File "/usr/lib64/python3.7/socket.py", line 727, in create_connection
    raise err
  File "/usr/lib64/python3.7/socket.py", line 716, in create_connection
    sock.connect(sa)
OSError: [Errno 101] Network is unreachable

During handling of the above exception, another exception occurred:

Traceback (most recent call last):
  File "/home/qiongwei/mycode/pythonenv/virtualenv/lib/python3.7/site-packages/gunicorn/arbiter.py", line 583, in spawn_worker
    worker.init_process()
  File "/home/qiongwei/mycode/pythonenv/virtualenv/lib/python3.7/site-packages/gunicorn/workers/base.py", line 119, in init_process
    self.load_wsgi()
  File "/home/qiongwei/mycode/pythonenv/virtualenv/lib/python3.7/site-packages/gunicorn/workers/base.py", line 144, in load_wsgi
    self.wsgi = self.app.wsgi()
  File "/home/qiongwei/mycode/pythonenv/virtualenv/lib/python3.7/site-packages/gunicorn/app/base.py", line 67, in wsgi
    self.callable = self.load()
  File "/home/qiongwei/mycode/pythonenv/virtualenv/lib/python3.7/site-packages/gunicorn/app/wsgiapp.py", line 49, in load
    return self.load_wsgiapp()
  File "/home/qiongwei/mycode/pythonenv/virtualenv/lib/python3.7/site-packages/gunicorn/app/wsgiapp.py", line 39, in load_wsgiapp
    return util.import_app(self.app_uri)
  File "/home/qiongwei/mycode/pythonenv/virtualenv/lib/python3.7/site-packages/gunicorn/util.py", line 358, in import_app
    mod = importlib.import_module(module)
  File "/home/qiongwei/mycode/pythonenv/virtualenv/lib/python3.7/importlib/__init__.py", line 127, in import_module
    return _bootstrap._gcd_import(name[level:], package, level)
  File "<frozen importlib._bootstrap>", line 1006, in _gcd_import
  File "<frozen importlib._bootstrap>", line 983, in _find_and_load
  File "<frozen importlib._bootstrap>", line 967, in _find_and_load_unlocked
  File "<frozen importlib._bootstrap>", line 677, in _load_unlocked
  File "<frozen importlib._bootstrap_external>", line 728, in exec_module
  File "<frozen importlib._bootstrap>", line 219, in _call_with_frames_removed
  File "/home/qiongwei/mycode/pythonenv/virtualenv/pingpongus/run.py", line 21, in <module>
    charset='utf8'
  File "/home/qiongwei/mycode/pythonenv/virtualenv/lib/python3.7/site-packages/pymysql/__init__.py", line 94, in Connect
    return Connection(*args, **kwargs)
  File "/home/qiongwei/mycode/pythonenv/virtualenv/lib/python3.7/site-packages/pymysql/connections.py", line 325, in __init__
    self.connect()
  File "/home/qiongwei/mycode/pythonenv/virtualenv/lib/python3.7/site-packages/pymysql/connections.py", line 630, in connect
    raise exc
pymysql.err.OperationalError: (2003, "Can't connect to MySQL server on '47.112.159.211' ([Errno 101] Network is unreachable)")
[2020-02-05 14:34:57 +0800] [1681] [INFO] Worker exiting (pid: 1681)
[2020-02-05 14:34:57 +0800] [1682] [ERROR] Exception in worker process
Traceback (most recent call last):
  File "/home/qiongwei/mycode/pythonenv/virtualenv/lib/python3.7/site-packages/pymysql/connections.py", line 583, in connect
    **kwargs)
  File "/usr/lib64/python3.7/socket.py", line 727, in create_connection
    raise err
  File "/usr/lib64/python3.7/socket.py", line 716, in create_connection
    sock.connect(sa)
OSError: [Errno 101] Network is unreachable

During handling of the above exception, another exception occurred:

Traceback (most recent call last):
  File "/home/qiongwei/mycode/pythonenv/virtualenv/lib/python3.7/site-packages/gunicorn/arbiter.py", line 583, in spawn_worker
    worker.init_process()
  File "/home/qiongwei/mycode/pythonenv/virtualenv/lib/python3.7/site-packages/gunicorn/workers/base.py", line 119, in init_process
    self.load_wsgi()
  File "/home/qiongwei/mycode/pythonenv/virtualenv/lib/python3.7/site-packages/gunicorn/workers/base.py", line 144, in load_wsgi
    self.wsgi = self.app.wsgi()
  File "/home/qiongwei/mycode/pythonenv/virtualenv/lib/python3.7/site-packages/gunicorn/app/base.py", line 67, in wsgi
    self.callable = self.load()
  File "/home/qiongwei/mycode/pythonenv/virtualenv/lib/python3.7/site-packages/gunicorn/app/wsgiapp.py", line 49, in load
    return self.load_wsgiapp()
  File "/home/qiongwei/mycode/pythonenv/virtualenv/lib/python3.7/site-packages/gunicorn/app/wsgiapp.py", line 39, in load_wsgiapp
    return util.import_app(self.app_uri)
  File "/home/qiongwei/mycode/pythonenv/virtualenv/lib/python3.7/site-packages/gunicorn/util.py", line 358, in import_app
    mod = importlib.import_module(module)
  File "/home/qiongwei/mycode/pythonenv/virtualenv/lib/python3.7/importlib/__init__.py", line 127, in import_module
    return _bootstrap._gcd_import(name[level:], package, level)
  File "<frozen importlib._bootstrap>", line 1006, in _gcd_import
  File "<frozen importlib._bootstrap>", line 983, in _find_and_load
  File "<frozen importlib._bootstrap>", line 967, in _find_and_load_unlocked
  File "<frozen importlib._bootstrap>", line 677, in _load_unlocked
  File "<frozen importlib._bootstrap_external>", line 728, in exec_module
  File "<frozen importlib._bootstrap>", line 219, in _call_with_frames_removed
  File "/home/qiongwei/mycode/pythonenv/virtualenv/pingpongus/run.py", line 21, in <module>
    charset='utf8'
  File "/home/qiongwei/mycode/pythonenv/virtualenv/lib/python3.7/site-packages/pymysql/__init__.py", line 94, in Connect
    return Connection(*args, **kwargs)
  File "/home/qiongwei/mycode/pythonenv/virtualenv/lib/python3.7/site-packages/pymysql/connections.py", line 325, in __init__
    self.connect()
  File "/home/qiongwei/mycode/pythonenv/virtualenv/lib/python3.7/site-packages/pymysql/connections.py", line 630, in connect
    raise exc
pymysql.err.OperationalError: (2003, "Can't connect to MySQL server on '47.112.159.211' ([Errno 101] Network is unreachable)")
[2020-02-05 14:34:57 +0800] [1682] [INFO] Worker exiting (pid: 1682)
[2020-02-05 15:11:40 +0800] [3010] [DEBUG] Current configuration:
  config: gunicorn_config_dev.py
  bind: ['0.0.0.0:8080']
  backlog: 2048
  workers: 12
  worker_class: sync
  threads: 1
  worker_connections: 1000
  max_requests: 0
  max_requests_jitter: 0
  timeout: 30
  graceful_timeout: 30
  keepalive: 2
  limit_request_line: 4094
  limit_request_fields: 100
  limit_request_field_size: 8190
  reload: False
  reload_engine: auto
  reload_extra_files: []
  spew: False
  check_config: False
  preload_app: False
  sendfile: None
  reuse_port: False
  chdir: /home/qiongwei/mycode/pythonenv/virtualenv/pingpongus
  daemon: False
  raw_env: []
  pidfile: /home/qiongwei/mycode/pythonenv/virtualenv/pingpongus/app/log/gunicorn.pid
  worker_tmp_dir: None
  user: 1000
  group: 1000
  umask: 0
  initgroups: False
  tmp_upload_dir: None
  secure_scheme_headers: {'X-FORWARDED-PROTOCOL': 'ssl', 'X-FORWARDED-PROTO': 'https', 'X-FORWARDED-SSL': 'on'}
  forwarded_allow_ips: ['127.0.0.1']
  accesslog: /home/qiongwei/mycode/pythonenv/virtualenv/pingpongus/app/log/access.log
  disable_redirect_access_to_syslog: False
  access_log_format: %(h)s %(l)s %(u)s %(t)s "%(r)s" %(s)s %(b)s "%(f)s" "%(a)s"
  errorlog: /home/qiongwei/mycode/pythonenv/virtualenv/pingpongus/app/log/debug.log
  loglevel: debug
  capture_output: False
  logger_class: gunicorn.glogging.Logger
  logconfig: None
  logconfig_dict: {}
  syslog_addr: udp://localhost:514
  syslog: False
  syslog_prefix: None
  syslog_facility: user
  enable_stdio_inheritance: False
  statsd_host: None
  dogstatsd_tags: 
  statsd_prefix: 
  proc_name: None
  default_proc_name: run:app
  pythonpath: None
  paste: None
  on_starting: <function OnStarting.on_starting at 0x7fea3673f440>
  on_reload: <function OnReload.on_reload at 0x7fea3673f560>
  when_ready: <function WhenReady.when_ready at 0x7fea3673f680>
  pre_fork: <function Prefork.pre_fork at 0x7fea3673f7a0>
  post_fork: <function Postfork.post_fork at 0x7fea3673f8c0>
  post_worker_init: <function PostWorkerInit.post_worker_init at 0x7fea3673f9e0>
  worker_int: <function WorkerInt.worker_int at 0x7fea3673fb00>
  worker_abort: <function WorkerAbort.worker_abort at 0x7fea3673fc20>
  pre_exec: <function PreExec.pre_exec at 0x7fea3673fd40>
  pre_request: <function PreRequest.pre_request at 0x7fea3673fe60>
  post_request: <function PostRequest.post_request at 0x7fea3673fef0>
  child_exit: <function ChildExit.child_exit at 0x7fea3660e050>
  worker_exit: <function WorkerExit.worker_exit at 0x7fea3660e170>
  nworkers_changed: <function NumWorkersChanged.nworkers_changed at 0x7fea3660e290>
  on_exit: <function OnExit.on_exit at 0x7fea3660e3b0>
  proxy_protocol: False
  proxy_allow_ips: ['127.0.0.1']
  keyfile: None
  certfile: None
  ssl_version: 2
  cert_reqs: 0
  ca_certs: None
  suppress_ragged_eofs: True
  do_handshake_on_connect: False
  ciphers: None
  raw_paste_global_conf: []
  strip_header_spaces: False
[2020-02-05 15:11:40 +0800] [3010] [INFO] Starting gunicorn 20.0.4
[2020-02-05 15:11:40 +0800] [3010] [DEBUG] Arbiter booted
[2020-02-05 15:11:40 +0800] [3010] [INFO] Listening at: http://0.0.0.0:8080 (3010)
[2020-02-05 15:11:40 +0800] [3010] [INFO] Using worker: sync
[2020-02-05 15:11:40 +0800] [3014] [INFO] Booting worker with pid: 3014
[2020-02-05 15:11:40 +0800] [3015] [INFO] Booting worker with pid: 3015
[2020-02-05 15:11:40 +0800] [3016] [INFO] Booting worker with pid: 3016
[2020-02-05 15:11:40 +0800] [3017] [INFO] Booting worker with pid: 3017
[2020-02-05 15:11:40 +0800] [3018] [INFO] Booting worker with pid: 3018
[2020-02-05 15:11:40 +0800] [3019] [INFO] Booting worker with pid: 3019
[2020-02-05 15:11:40 +0800] [3020] [INFO] Booting worker with pid: 3020
[2020-02-05 15:11:40 +0800] [3021] [INFO] Booting worker with pid: 3021
[2020-02-05 15:11:40 +0800] [3022] [INFO] Booting worker with pid: 3022
[2020-02-05 15:11:40 +0800] [3023] [INFO] Booting worker with pid: 3023
[2020-02-05 15:11:40 +0800] [3025] [INFO] Booting worker with pid: 3025
[2020-02-05 15:11:40 +0800] [3026] [INFO] Booting worker with pid: 3026
[2020-02-05 15:11:40 +0800] [3010] [DEBUG] 12 workers
[2020-02-05 15:11:43 +0800] [3018] [DEBUG] GET /h5snake
[2020-02-05 15:12:31 +0800] [3023] [DEBUG] GET /h5snake
[2020-02-05 15:13:04 +0800] [3015] [DEBUG] GET /h5snake
[2020-02-05 15:13:53 +0800] [3025] [DEBUG] GET /h5snake
[2020-02-05 15:16:02 +0800] [3022] [DEBUG] GET /h5snake
[2020-02-05 15:16:50 +0800] [3025] [DEBUG] GET /h5snake
[2020-02-05 15:18:29 +0800] [3017] [DEBUG] GET /h5snake
[2020-02-05 15:19:59 +0800] [3025] [DEBUG] GET /h5snake
[2020-02-05 15:23:38 +0800] [3021] [DEBUG] GET /h5snake
[2020-02-05 15:23:54 +0800] [3018] [DEBUG] GET /h5snake
[2020-02-05 17:07:45 +0800] [3010] [CRITICAL] WORKER TIMEOUT (pid:3014)
[2020-02-05 17:07:45 +0800] [3010] [CRITICAL] WORKER TIMEOUT (pid:3015)
[2020-02-05 17:07:45 +0800] [3010] [CRITICAL] WORKER TIMEOUT (pid:3016)
[2020-02-05 17:07:45 +0800] [3010] [CRITICAL] WORKER TIMEOUT (pid:3017)
[2020-02-05 17:07:45 +0800] [3010] [CRITICAL] WORKER TIMEOUT (pid:3018)
[2020-02-05 17:07:45 +0800] [3014] [INFO] Worker exiting (pid: 3014)
[2020-02-05 17:07:45 +0800] [3010] [CRITICAL] WORKER TIMEOUT (pid:3019)
[2020-02-05 17:07:45 +0800] [3015] [INFO] Worker exiting (pid: 3015)
[2020-02-05 17:07:45 +0800] [3010] [CRITICAL] WORKER TIMEOUT (pid:3020)
[2020-02-05 17:07:45 +0800] [3016] [INFO] Worker exiting (pid: 3016)
[2020-02-05 17:07:45 +0800] [3010] [CRITICAL] WORKER TIMEOUT (pid:3021)
[2020-02-05 17:07:45 +0800] [3017] [INFO] Worker exiting (pid: 3017)
[2020-02-05 17:07:45 +0800] [3018] [INFO] Worker exiting (pid: 3018)
[2020-02-05 17:07:45 +0800] [3010] [CRITICAL] WORKER TIMEOUT (pid:3022)
[2020-02-05 17:07:45 +0800] [3010] [CRITICAL] WORKER TIMEOUT (pid:3023)
[2020-02-05 17:07:45 +0800] [3019] [INFO] Worker exiting (pid: 3019)
[2020-02-05 17:07:45 +0800] [3020] [INFO] Worker exiting (pid: 3020)
[2020-02-05 17:07:45 +0800] [3021] [INFO] Worker exiting (pid: 3021)
[2020-02-05 17:07:45 +0800] [3023] [INFO] Worker exiting (pid: 3023)
[2020-02-05 17:07:45 +0800] [3022] [INFO] Worker exiting (pid: 3022)
[2020-02-05 17:07:45 +0800] [3010] [CRITICAL] WORKER TIMEOUT (pid:3025)
[2020-02-05 17:07:45 +0800] [3010] [CRITICAL] WORKER TIMEOUT (pid:3026)
[2020-02-05 17:07:45 +0800] [3026] [INFO] Worker exiting (pid: 3026)
[2020-02-05 17:07:45 +0800] [3025] [INFO] Worker exiting (pid: 3025)
[2020-02-05 17:07:45 +0800] [3010] [DEBUG] 11 workers
[2020-02-05 17:07:45 +0800] [23634] [INFO] Booting worker with pid: 23634
[2020-02-05 17:07:45 +0800] [23635] [INFO] Booting worker with pid: 23635
[2020-02-05 17:07:45 +0800] [23636] [INFO] Booting worker with pid: 23636
[2020-02-05 17:07:45 +0800] [23637] [INFO] Booting worker with pid: 23637
[2020-02-05 17:07:45 +0800] [3010] [DEBUG] 4 workers
[2020-02-05 17:07:45 +0800] [23638] [INFO] Booting worker with pid: 23638
[2020-02-05 17:07:45 +0800] [23635] [ERROR] Exception in worker process
Traceback (most recent call last):
  File "/home/qiongwei/mycode/pythonenv/virtualenv/lib/python3.7/site-packages/pymysql/connections.py", line 583, in connect
    **kwargs)
  File "/usr/lib64/python3.7/socket.py", line 727, in create_connection
    raise err
  File "/usr/lib64/python3.7/socket.py", line 716, in create_connection
    sock.connect(sa)
OSError: [Errno 101] Network is unreachable

During handling of the above exception, another exception occurred:

Traceback (most recent call last):
  File "/home/qiongwei/mycode/pythonenv/virtualenv/lib/python3.7/site-packages/gunicorn/arbiter.py", line 583, in spawn_worker
    worker.init_process()
  File "/home/qiongwei/mycode/pythonenv/virtualenv/lib/python3.7/site-packages/gunicorn/workers/base.py", line 119, in init_process
    self.load_wsgi()
  File "/home/qiongwei/mycode/pythonenv/virtualenv/lib/python3.7/site-packages/gunicorn/workers/base.py", line 144, in load_wsgi
    self.wsgi = self.app.wsgi()
  File "/home/qiongwei/mycode/pythonenv/virtualenv/lib/python3.7/site-packages/gunicorn/app/base.py", line 67, in wsgi
    self.callable = self.load()
  File "/home/qiongwei/mycode/pythonenv/virtualenv/lib/python3.7/site-packages/gunicorn/app/wsgiapp.py", line 49, in load
    return self.load_wsgiapp()
  File "/home/qiongwei/mycode/pythonenv/virtualenv/lib/python3.7/site-packages/gunicorn/app/wsgiapp.py", line 39, in load_wsgiapp
    return util.import_app(self.app_uri)
  File "/home/qiongwei/mycode/pythonenv/virtualenv/lib/python3.7/site-packages/gunicorn/util.py", line 358, in import_app
    mod = importlib.import_module(module)
  File "/home/qiongwei/mycode/pythonenv/virtualenv/lib/python3.7/importlib/__init__.py", line 127, in import_module
    return _bootstrap._gcd_import(name[level:], package, level)
  File "<frozen importlib._bootstrap>", line 1006, in _gcd_import
  File "<frozen importlib._bootstrap>", line 983, in _find_and_load
  File "<frozen importlib._bootstrap>", line 967, in _find_and_load_unlocked
  File "<frozen importlib._bootstrap>", line 677, in _load_unlocked
  File "<frozen importlib._bootstrap_external>", line 728, in exec_module
  File "<frozen importlib._bootstrap>", line 219, in _call_with_frames_removed
  File "/home/qiongwei/mycode/pythonenv/virtualenv/pingpongus/run.py", line 21, in <module>
    charset='utf8'
  File "/home/qiongwei/mycode/pythonenv/virtualenv/lib/python3.7/site-packages/pymysql/__init__.py", line 94, in Connect
    return Connection(*args, **kwargs)
  File "/home/qiongwei/mycode/pythonenv/virtualenv/lib/python3.7/site-packages/pymysql/connections.py", line 325, in __init__
    self.connect()
  File "/home/qiongwei/mycode/pythonenv/virtualenv/lib/python3.7/site-packages/pymysql/connections.py", line 630, in connect
    raise exc
pymysql.err.OperationalError: (2003, "Can't connect to MySQL server on '47.112.159.211' ([Errno 101] Network is unreachable)")
[2020-02-05 17:07:45 +0800] [23635] [INFO] Worker exiting (pid: 23635)
[2020-02-05 17:07:45 +0800] [23636] [ERROR] Exception in worker process
Traceback (most recent call last):
  File "/home/qiongwei/mycode/pythonenv/virtualenv/lib/python3.7/site-packages/pymysql/connections.py", line 583, in connect
    **kwargs)
  File "/usr/lib64/python3.7/socket.py", line 727, in create_connection
    raise err
  File "/usr/lib64/python3.7/socket.py", line 716, in create_connection
    sock.connect(sa)
OSError: [Errno 101] Network is unreachable

During handling of the above exception, another exception occurred:

Traceback (most recent call last):
  File "/home/qiongwei/mycode/pythonenv/virtualenv/lib/python3.7/site-packages/gunicorn/arbiter.py", line 583, in spawn_worker
    worker.init_process()
  File "/home/qiongwei/mycode/pythonenv/virtualenv/lib/python3.7/site-packages/gunicorn/workers/base.py", line 119, in init_process
    self.load_wsgi()
  File "/home/qiongwei/mycode/pythonenv/virtualenv/lib/python3.7/site-packages/gunicorn/workers/base.py", line 144, in load_wsgi
    self.wsgi = self.app.wsgi()
  File "/home/qiongwei/mycode/pythonenv/virtualenv/lib/python3.7/site-packages/gunicorn/app/base.py", line 67, in wsgi
    self.callable = self.load()
  File "/home/qiongwei/mycode/pythonenv/virtualenv/lib/python3.7/site-packages/gunicorn/app/wsgiapp.py", line 49, in load
    return self.load_wsgiapp()
  File "/home/qiongwei/mycode/pythonenv/virtualenv/lib/python3.7/site-packages/gunicorn/app/wsgiapp.py", line 39, in load_wsgiapp
    return util.import_app(self.app_uri)
  File "/home/qiongwei/mycode/pythonenv/virtualenv/lib/python3.7/site-packages/gunicorn/util.py", line 358, in import_app
    mod = importlib.import_module(module)
  File "/home/qiongwei/mycode/pythonenv/virtualenv/lib/python3.7/importlib/__init__.py", line 127, in import_module
    return _bootstrap._gcd_import(name[level:], package, level)
  File "<frozen importlib._bootstrap>", line 1006, in _gcd_import
  File "<frozen importlib._bootstrap>", line 983, in _find_and_load
  File "<frozen importlib._bootstrap>", line 967, in _find_and_load_unlocked
  File "<frozen importlib._bootstrap>", line 677, in _load_unlocked
  File "<frozen importlib._bootstrap_external>", line 728, in exec_module
  File "<frozen importlib._bootstrap>", line 219, in _call_with_frames_removed
  File "/home/qiongwei/mycode/pythonenv/virtualenv/pingpongus/run.py", line 21, in <module>
    charset='utf8'
  File "/home/qiongwei/mycode/pythonenv/virtualenv/lib/python3.7/site-packages/pymysql/__init__.py", line 94, in Connect
    return Connection(*args, **kwargs)
  File "/home/qiongwei/mycode/pythonenv/virtualenv/lib/python3.7/site-packages/pymysql/connections.py", line 325, in __init__
    self.connect()
  File "/home/qiongwei/mycode/pythonenv/virtualenv/lib/python3.7/site-packages/pymysql/connections.py", line 630, in connect
    raise exc
pymysql.err.OperationalError: (2003, "Can't connect to MySQL server on '47.112.159.211' ([Errno 101] Network is unreachable)")
[2020-02-05 17:07:45 +0800] [23636] [INFO] Worker exiting (pid: 23636)
[2020-02-05 17:07:45 +0800] [23639] [INFO] Booting worker with pid: 23639
[2020-02-05 17:07:45 +0800] [23634] [ERROR] Exception in worker process
Traceback (most recent call last):
  File "/home/qiongwei/mycode/pythonenv/virtualenv/lib/python3.7/site-packages/pymysql/connections.py", line 583, in connect
    **kwargs)
  File "/usr/lib64/python3.7/socket.py", line 727, in create_connection
    raise err
  File "/usr/lib64/python3.7/socket.py", line 716, in create_connection
    sock.connect(sa)
OSError: [Errno 101] Network is unreachable

During handling of the above exception, another exception occurred:

Traceback (most recent call last):
  File "/home/qiongwei/mycode/pythonenv/virtualenv/lib/python3.7/site-packages/gunicorn/arbiter.py", line 583, in spawn_worker
    worker.init_process()
  File "/home/qiongwei/mycode/pythonenv/virtualenv/lib/python3.7/site-packages/gunicorn/workers/base.py", line 119, in init_process
    self.load_wsgi()
  File "/home/qiongwei/mycode/pythonenv/virtualenv/lib/python3.7/site-packages/gunicorn/workers/base.py", line 144, in load_wsgi
    self.wsgi = self.app.wsgi()
  File "/home/qiongwei/mycode/pythonenv/virtualenv/lib/python3.7/site-packages/gunicorn/app/base.py", line 67, in wsgi
    self.callable = self.load()
  File "/home/qiongwei/mycode/pythonenv/virtualenv/lib/python3.7/site-packages/gunicorn/app/wsgiapp.py", line 49, in load
    return self.load_wsgiapp()
  File "/home/qiongwei/mycode/pythonenv/virtualenv/lib/python3.7/site-packages/gunicorn/app/wsgiapp.py", line 39, in load_wsgiapp
    return util.import_app(self.app_uri)
  File "/home/qiongwei/mycode/pythonenv/virtualenv/lib/python3.7/site-packages/gunicorn/util.py", line 358, in import_app
    mod = importlib.import_module(module)
  File "/home/qiongwei/mycode/pythonenv/virtualenv/lib/python3.7/importlib/__init__.py", line 127, in import_module
    return _bootstrap._gcd_import(name[level:], package, level)
  File "<frozen importlib._bootstrap>", line 1006, in _gcd_import
  File "<frozen importlib._bootstrap>", line 983, in _find_and_load
  File "<frozen importlib._bootstrap>", line 967, in _find_and_load_unlocked
  File "<frozen importlib._bootstrap>", line 677, in _load_unlocked
  File "<frozen importlib._bootstrap_external>", line 728, in exec_module
  File "<frozen importlib._bootstrap>", line 219, in _call_with_frames_removed
  File "/home/qiongwei/mycode/pythonenv/virtualenv/pingpongus/run.py", line 21, in <module>
    charset='utf8'
  File "/home/qiongwei/mycode/pythonenv/virtualenv/lib/python3.7/site-packages/pymysql/__init__.py", line 94, in Connect
    return Connection(*args, **kwargs)
  File "/home/qiongwei/mycode/pythonenv/virtualenv/lib/python3.7/site-packages/pymysql/connections.py", line 325, in __init__
    self.connect()
  File "/home/qiongwei/mycode/pythonenv/virtualenv/lib/python3.7/site-packages/pymysql/connections.py", line 630, in connect
    raise exc
pymysql.err.OperationalError: (2003, "Can't connect to MySQL server on '47.112.159.211' ([Errno 101] Network is unreachable)")
[2020-02-05 17:07:45 +0800] [23634] [INFO] Worker exiting (pid: 23634)
[2020-02-05 17:07:45 +0800] [23640] [INFO] Booting worker with pid: 23640
[2020-02-05 17:07:45 +0800] [23637] [ERROR] Exception in worker process
Traceback (most recent call last):
  File "/home/qiongwei/mycode/pythonenv/virtualenv/lib/python3.7/site-packages/pymysql/connections.py", line 583, in connect
    **kwargs)
  File "/usr/lib64/python3.7/socket.py", line 727, in create_connection
    raise err
  File "/usr/lib64/python3.7/socket.py", line 716, in create_connection
    sock.connect(sa)
OSError: [Errno 101] Network is unreachable

During handling of the above exception, another exception occurred:

Traceback (most recent call last):
  File "/home/qiongwei/mycode/pythonenv/virtualenv/lib/python3.7/site-packages/gunicorn/arbiter.py", line 583, in spawn_worker
    worker.init_process()
  File "/home/qiongwei/mycode/pythonenv/virtualenv/lib/python3.7/site-packages/gunicorn/workers/base.py", line 119, in init_process
    self.load_wsgi()
  File "/home/qiongwei/mycode/pythonenv/virtualenv/lib/python3.7/site-packages/gunicorn/workers/base.py", line 144, in load_wsgi
    self.wsgi = self.app.wsgi()
  File "/home/qiongwei/mycode/pythonenv/virtualenv/lib/python3.7/site-packages/gunicorn/app/base.py", line 67, in wsgi
    self.callable = self.load()
  File "/home/qiongwei/mycode/pythonenv/virtualenv/lib/python3.7/site-packages/gunicorn/app/wsgiapp.py", line 49, in load
    return self.load_wsgiapp()
  File "/home/qiongwei/mycode/pythonenv/virtualenv/lib/python3.7/site-packages/gunicorn/app/wsgiapp.py", line 39, in load_wsgiapp
    return util.import_app(self.app_uri)
  File "/home/qiongwei/mycode/pythonenv/virtualenv/lib/python3.7/site-packages/gunicorn/util.py", line 358, in import_app
    mod = importlib.import_module(module)
  File "/home/qiongwei/mycode/pythonenv/virtualenv/lib/python3.7/importlib/__init__.py", line 127, in import_module
    return _bootstrap._gcd_import(name[level:], package, level)
  File "<frozen importlib._bootstrap>", line 1006, in _gcd_import
  File "<frozen importlib._bootstrap>", line 983, in _find_and_load
  File "<frozen importlib._bootstrap>", line 967, in _find_and_load_unlocked
  File "<frozen importlib._bootstrap>", line 677, in _load_unlocked
  File "<frozen importlib._bootstrap_external>", line 728, in exec_module
  File "<frozen importlib._bootstrap>", line 219, in _call_with_frames_removed
  File "/home/qiongwei/mycode/pythonenv/virtualenv/pingpongus/run.py", line 21, in <module>
    charset='utf8'
  File "/home/qiongwei/mycode/pythonenv/virtualenv/lib/python3.7/site-packages/pymysql/__init__.py", line 94, in Connect
    return Connection(*args, **kwargs)
  File "/home/qiongwei/mycode/pythonenv/virtualenv/lib/python3.7/site-packages/pymysql/connections.py", line 325, in __init__
    self.connect()
  File "/home/qiongwei/mycode/pythonenv/virtualenv/lib/python3.7/site-packages/pymysql/connections.py", line 630, in connect
    raise exc
pymysql.err.OperationalError: (2003, "Can't connect to MySQL server on '47.112.159.211' ([Errno 101] Network is unreachable)")
[2020-02-05 17:07:45 +0800] [23637] [INFO] Worker exiting (pid: 23637)
[2020-02-05 17:07:45 +0800] [23638] [ERROR] Exception in worker process
Traceback (most recent call last):
  File "/home/qiongwei/mycode/pythonenv/virtualenv/lib/python3.7/site-packages/pymysql/connections.py", line 583, in connect
    **kwargs)
  File "/usr/lib64/python3.7/socket.py", line 727, in create_connection
    raise err
  File "/usr/lib64/python3.7/socket.py", line 716, in create_connection
    sock.connect(sa)
OSError: [Errno 101] Network is unreachable

During handling of the above exception, another exception occurred:

Traceback (most recent call last):
  File "/home/qiongwei/mycode/pythonenv/virtualenv/lib/python3.7/site-packages/gunicorn/arbiter.py", line 583, in spawn_worker
    worker.init_process()
  File "/home/qiongwei/mycode/pythonenv/virtualenv/lib/python3.7/site-packages/gunicorn/workers/base.py", line 119, in init_process
    self.load_wsgi()
  File "/home/qiongwei/mycode/pythonenv/virtualenv/lib/python3.7/site-packages/gunicorn/workers/base.py", line 144, in load_wsgi
    self.wsgi = self.app.wsgi()
  File "/home/qiongwei/mycode/pythonenv/virtualenv/lib/python3.7/site-packages/gunicorn/app/base.py", line 67, in wsgi
    self.callable = self.load()
  File "/home/qiongwei/mycode/pythonenv/virtualenv/lib/python3.7/site-packages/gunicorn/app/wsgiapp.py", line 49, in load
    return self.load_wsgiapp()
  File "/home/qiongwei/mycode/pythonenv/virtualenv/lib/python3.7/site-packages/gunicorn/app/wsgiapp.py", line 39, in load_wsgiapp
    return util.import_app(self.app_uri)
  File "/home/qiongwei/mycode/pythonenv/virtualenv/lib/python3.7/site-packages/gunicorn/util.py", line 358, in import_app
    mod = importlib.import_module(module)
  File "/home/qiongwei/mycode/pythonenv/virtualenv/lib/python3.7/importlib/__init__.py", line 127, in import_module
    return _bootstrap._gcd_import(name[level:], package, level)
  File "<frozen importlib._bootstrap>", line 1006, in _gcd_import
  File "<frozen importlib._bootstrap>", line 983, in _find_and_load
  File "<frozen importlib._bootstrap>", line 967, in _find_and_load_unlocked
  File "<frozen importlib._bootstrap>", line 677, in _load_unlocked
  File "<frozen importlib._bootstrap_external>", line 728, in exec_module
  File "<frozen importlib._bootstrap>", line 219, in _call_with_frames_removed
  File "/home/qiongwei/mycode/pythonenv/virtualenv/pingpongus/run.py", line 21, in <module>
    charset='utf8'
  File "/home/qiongwei/mycode/pythonenv/virtualenv/lib/python3.7/site-packages/pymysql/__init__.py", line 94, in Connect
    return Connection(*args, **kwargs)
  File "/home/qiongwei/mycode/pythonenv/virtualenv/lib/python3.7/site-packages/pymysql/connections.py", line 325, in __init__
    self.connect()
  File "/home/qiongwei/mycode/pythonenv/virtualenv/lib/python3.7/site-packages/pymysql/connections.py", line 630, in connect
    raise exc
pymysql.err.OperationalError: (2003, "Can't connect to MySQL server on '47.112.159.211' ([Errno 101] Network is unreachable)")
[2020-02-05 17:07:45 +0800] [23638] [INFO] Worker exiting (pid: 23638)
[2020-02-05 17:07:45 +0800] [23639] [ERROR] Exception in worker process
Traceback (most recent call last):
  File "/home/qiongwei/mycode/pythonenv/virtualenv/lib/python3.7/site-packages/pymysql/connections.py", line 583, in connect
    **kwargs)
  File "/usr/lib64/python3.7/socket.py", line 727, in create_connection
    raise err
  File "/usr/lib64/python3.7/socket.py", line 716, in create_connection
    sock.connect(sa)
OSError: [Errno 101] Network is unreachable

During handling of the above exception, another exception occurred:

Traceback (most recent call last):
  File "/home/qiongwei/mycode/pythonenv/virtualenv/lib/python3.7/site-packages/gunicorn/arbiter.py", line 583, in spawn_worker
    worker.init_process()
  File "/home/qiongwei/mycode/pythonenv/virtualenv/lib/python3.7/site-packages/gunicorn/workers/base.py", line 119, in init_process
    self.load_wsgi()
  File "/home/qiongwei/mycode/pythonenv/virtualenv/lib/python3.7/site-packages/gunicorn/workers/base.py", line 144, in load_wsgi
    self.wsgi = self.app.wsgi()
  File "/home/qiongwei/mycode/pythonenv/virtualenv/lib/python3.7/site-packages/gunicorn/app/base.py", line 67, in wsgi
    self.callable = self.load()
  File "/home/qiongwei/mycode/pythonenv/virtualenv/lib/python3.7/site-packages/gunicorn/app/wsgiapp.py", line 49, in load
    return self.load_wsgiapp()
  File "/home/qiongwei/mycode/pythonenv/virtualenv/lib/python3.7/site-packages/gunicorn/app/wsgiapp.py", line 39, in load_wsgiapp
    return util.import_app(self.app_uri)
  File "/home/qiongwei/mycode/pythonenv/virtualenv/lib/python3.7/site-packages/gunicorn/util.py", line 358, in import_app
    mod = importlib.import_module(module)
  File "/home/qiongwei/mycode/pythonenv/virtualenv/lib/python3.7/importlib/__init__.py", line 127, in import_module
    return _bootstrap._gcd_import(name[level:], package, level)
  File "<frozen importlib._bootstrap>", line 1006, in _gcd_import
  File "<frozen importlib._bootstrap>", line 983, in _find_and_load
  File "<frozen importlib._bootstrap>", line 967, in _find_and_load_unlocked
  File "<frozen importlib._bootstrap>", line 677, in _load_unlocked
  File "<frozen importlib._bootstrap_external>", line 728, in exec_module
  File "<frozen importlib._bootstrap>", line 219, in _call_with_frames_removed
  File "/home/qiongwei/mycode/pythonenv/virtualenv/pingpongus/run.py", line 21, in <module>
    charset='utf8'
  File "/home/qiongwei/mycode/pythonenv/virtualenv/lib/python3.7/site-packages/pymysql/__init__.py", line 94, in Connect
    return Connection(*args, **kwargs)
  File "/home/qiongwei/mycode/pythonenv/virtualenv/lib/python3.7/site-packages/pymysql/connections.py", line 325, in __init__
    self.connect()
  File "/home/qiongwei/mycode/pythonenv/virtualenv/lib/python3.7/site-packages/pymysql/connections.py", line 630, in connect
    raise exc
pymysql.err.OperationalError: (2003, "Can't connect to MySQL server on '47.112.159.211' ([Errno 101] Network is unreachable)")
[2020-02-05 17:07:45 +0800] [23639] [INFO] Worker exiting (pid: 23639)
[2020-02-05 17:07:45 +0800] [23640] [ERROR] Exception in worker process
Traceback (most recent call last):
  File "/home/qiongwei/mycode/pythonenv/virtualenv/lib/python3.7/site-packages/pymysql/connections.py", line 583, in connect
    **kwargs)
  File "/usr/lib64/python3.7/socket.py", line 727, in create_connection
    raise err
  File "/usr/lib64/python3.7/socket.py", line 716, in create_connection
    sock.connect(sa)
OSError: [Errno 101] Network is unreachable

During handling of the above exception, another exception occurred:

Traceback (most recent call last):
  File "/home/qiongwei/mycode/pythonenv/virtualenv/lib/python3.7/site-packages/gunicorn/arbiter.py", line 583, in spawn_worker
    worker.init_process()
  File "/home/qiongwei/mycode/pythonenv/virtualenv/lib/python3.7/site-packages/gunicorn/workers/base.py", line 119, in init_process
    self.load_wsgi()
  File "/home/qiongwei/mycode/pythonenv/virtualenv/lib/python3.7/site-packages/gunicorn/workers/base.py", line 144, in load_wsgi
    self.wsgi = self.app.wsgi()
  File "/home/qiongwei/mycode/pythonenv/virtualenv/lib/python3.7/site-packages/gunicorn/app/base.py", line 67, in wsgi
    self.callable = self.load()
  File "/home/qiongwei/mycode/pythonenv/virtualenv/lib/python3.7/site-packages/gunicorn/app/wsgiapp.py", line 49, in load
    return self.load_wsgiapp()
  File "/home/qiongwei/mycode/pythonenv/virtualenv/lib/python3.7/site-packages/gunicorn/app/wsgiapp.py", line 39, in load_wsgiapp
    return util.import_app(self.app_uri)
  File "/home/qiongwei/mycode/pythonenv/virtualenv/lib/python3.7/site-packages/gunicorn/util.py", line 358, in import_app
    mod = importlib.import_module(module)
  File "/home/qiongwei/mycode/pythonenv/virtualenv/lib/python3.7/importlib/__init__.py", line 127, in import_module
    return _bootstrap._gcd_import(name[level:], package, level)
  File "<frozen importlib._bootstrap>", line 1006, in _gcd_import
  File "<frozen importlib._bootstrap>", line 983, in _find_and_load
  File "<frozen importlib._bootstrap>", line 967, in _find_and_load_unlocked
  File "<frozen importlib._bootstrap>", line 677, in _load_unlocked
  File "<frozen importlib._bootstrap_external>", line 728, in exec_module
  File "<frozen importlib._bootstrap>", line 219, in _call_with_frames_removed
  File "/home/qiongwei/mycode/pythonenv/virtualenv/pingpongus/run.py", line 21, in <module>
    charset='utf8'
  File "/home/qiongwei/mycode/pythonenv/virtualenv/lib/python3.7/site-packages/pymysql/__init__.py", line 94, in Connect
    return Connection(*args, **kwargs)
  File "/home/qiongwei/mycode/pythonenv/virtualenv/lib/python3.7/site-packages/pymysql/connections.py", line 325, in __init__
    self.connect()
  File "/home/qiongwei/mycode/pythonenv/virtualenv/lib/python3.7/site-packages/pymysql/connections.py", line 630, in connect
    raise exc
pymysql.err.OperationalError: (2003, "Can't connect to MySQL server on '47.112.159.211' ([Errno 101] Network is unreachable)")
[2020-02-05 17:07:45 +0800] [23640] [INFO] Worker exiting (pid: 23640)
[2020-02-05 17:28:41 +0800] [24980] [DEBUG] Current configuration:
  config: gunicorn_config_dev.py
  bind: ['0.0.0.0:8080']
  backlog: 2048
  workers: 12
  worker_class: sync
  threads: 1
  worker_connections: 1000
  max_requests: 0
  max_requests_jitter: 0
  timeout: 30
  graceful_timeout: 30
  keepalive: 2
  limit_request_line: 4094
  limit_request_fields: 100
  limit_request_field_size: 8190
  reload: False
  reload_engine: auto
  reload_extra_files: []
  spew: False
  check_config: False
  preload_app: False
  sendfile: None
  reuse_port: False
  chdir: /home/qiongwei/mycode/pythonenv/virtualenv/pingpongus
  daemon: False
  raw_env: []
  pidfile: /home/qiongwei/mycode/pythonenv/virtualenv/pingpongus/app/log/gunicorn.pid
  worker_tmp_dir: None
  user: 1000
  group: 1000
  umask: 0
  initgroups: False
  tmp_upload_dir: None
  secure_scheme_headers: {'X-FORWARDED-PROTOCOL': 'ssl', 'X-FORWARDED-PROTO': 'https', 'X-FORWARDED-SSL': 'on'}
  forwarded_allow_ips: ['127.0.0.1']
  accesslog: /home/qiongwei/mycode/pythonenv/virtualenv/pingpongus/app/log/access.log
  disable_redirect_access_to_syslog: False
  access_log_format: %(h)s %(l)s %(u)s %(t)s "%(r)s" %(s)s %(b)s "%(f)s" "%(a)s"
  errorlog: /home/qiongwei/mycode/pythonenv/virtualenv/pingpongus/app/log/debug.log
  loglevel: debug
  capture_output: False
  logger_class: gunicorn.glogging.Logger
  logconfig: None
  logconfig_dict: {}
  syslog_addr: udp://localhost:514
  syslog: False
  syslog_prefix: None
  syslog_facility: user
  enable_stdio_inheritance: False
  statsd_host: None
  dogstatsd_tags: 
  statsd_prefix: 
  proc_name: None
  default_proc_name: run:app
  pythonpath: None
  paste: None
  on_starting: <function OnStarting.on_starting at 0x7f3897e63440>
  on_reload: <function OnReload.on_reload at 0x7f3897e63560>
  when_ready: <function WhenReady.when_ready at 0x7f3897e63680>
  pre_fork: <function Prefork.pre_fork at 0x7f3897e637a0>
  post_fork: <function Postfork.post_fork at 0x7f3897e638c0>
  post_worker_init: <function PostWorkerInit.post_worker_init at 0x7f3897e639e0>
  worker_int: <function WorkerInt.worker_int at 0x7f3897e63b00>
  worker_abort: <function WorkerAbort.worker_abort at 0x7f3897e63c20>
  pre_exec: <function PreExec.pre_exec at 0x7f3897e63d40>
  pre_request: <function PreRequest.pre_request at 0x7f3897e63e60>
  post_request: <function PostRequest.post_request at 0x7f3897e63ef0>
  child_exit: <function ChildExit.child_exit at 0x7f3897d32050>
  worker_exit: <function WorkerExit.worker_exit at 0x7f3897d32170>
  nworkers_changed: <function NumWorkersChanged.nworkers_changed at 0x7f3897d32290>
  on_exit: <function OnExit.on_exit at 0x7f3897d323b0>
  proxy_protocol: False
  proxy_allow_ips: ['127.0.0.1']
  keyfile: None
  certfile: None
  ssl_version: 2
  cert_reqs: 0
  ca_certs: None
  suppress_ragged_eofs: True
  do_handshake_on_connect: False
  ciphers: None
  raw_paste_global_conf: []
  strip_header_spaces: False
[2020-02-05 17:28:41 +0800] [24980] [INFO] Starting gunicorn 20.0.4
[2020-02-05 17:28:41 +0800] [24980] [DEBUG] Arbiter booted
[2020-02-05 17:28:41 +0800] [24980] [INFO] Listening at: http://0.0.0.0:8080 (24980)
[2020-02-05 17:28:41 +0800] [24980] [INFO] Using worker: sync
[2020-02-05 17:28:41 +0800] [24983] [INFO] Booting worker with pid: 24983
[2020-02-05 17:28:41 +0800] [24985] [INFO] Booting worker with pid: 24985
[2020-02-05 17:28:41 +0800] [24986] [INFO] Booting worker with pid: 24986
[2020-02-05 17:28:41 +0800] [24987] [INFO] Booting worker with pid: 24987
[2020-02-05 17:28:41 +0800] [24989] [INFO] Booting worker with pid: 24989
[2020-02-05 17:28:41 +0800] [24990] [INFO] Booting worker with pid: 24990
[2020-02-05 17:28:41 +0800] [24991] [INFO] Booting worker with pid: 24991
[2020-02-05 17:28:41 +0800] [24992] [INFO] Booting worker with pid: 24992
[2020-02-05 17:28:41 +0800] [24993] [INFO] Booting worker with pid: 24993
[2020-02-05 17:28:41 +0800] [24994] [INFO] Booting worker with pid: 24994
[2020-02-05 17:28:41 +0800] [24995] [INFO] Booting worker with pid: 24995
[2020-02-05 17:28:41 +0800] [24996] [INFO] Booting worker with pid: 24996
[2020-02-05 17:28:41 +0800] [24980] [DEBUG] 12 workers
[2020-02-05 17:28:42 +0800] [24989] [DEBUG] GET /h5snake
[2020-02-05 17:29:07 +0800] [24995] [DEBUG] GET /h5snake
[2020-02-05 17:29:53 +0800] [24986] [DEBUG] GET /h5snake
[2020-02-05 17:30:27 +0800] [24994] [DEBUG] GET /h5snake
[2020-02-05 17:34:06 +0800] [24983] [DEBUG] GET /h5snake
[2020-02-05 17:37:47 +0800] [24991] [DEBUG] GET /h5snake
[2020-02-05 17:40:16 +0800] [24987] [DEBUG] GET /h5snake
[2020-02-05 17:40:28 +0800] [24989] [DEBUG] GET /h5snake
[2020-02-05 17:42:15 +0800] [24985] [DEBUG] GET /h5snake
[2020-02-05 17:44:56 +0800] [24980] [INFO] Handling signal: int
[2020-02-05 17:44:56 +0800] [24985] [INFO] Worker exiting (pid: 24985)
[2020-02-05 17:44:56 +0800] [24987] [INFO] Worker exiting (pid: 24987)
[2020-02-05 17:44:56 +0800] [24989] [INFO] Worker exiting (pid: 24989)
[2020-02-05 17:44:56 +0800] [24983] [INFO] Worker exiting (pid: 24983)
[2020-02-05 17:44:56 +0800] [24995] [INFO] Worker exiting (pid: 24995)
[2020-02-05 17:44:56 +0800] [24991] [INFO] Worker exiting (pid: 24991)
[2020-02-05 17:44:56 +0800] [24994] [INFO] Worker exiting (pid: 24994)
[2020-02-05 17:44:56 +0800] [24993] [INFO] Worker exiting (pid: 24993)
[2020-02-05 17:44:56 +0800] [24992] [INFO] Worker exiting (pid: 24992)
[2020-02-05 17:44:56 +0800] [24996] [INFO] Worker exiting (pid: 24996)
[2020-02-05 17:44:56 +0800] [24990] [INFO] Worker exiting (pid: 24990)
[2020-02-05 17:44:56 +0800] [24986] [INFO] Worker exiting (pid: 24986)
[2020-02-05 17:44:56 +0800] [24980] [INFO] Shutting down: Master
[2020-02-05 17:44:57 +0800] [26136] [DEBUG] Current configuration:
  config: gunicorn_config_dev.py
  bind: ['0.0.0.0:8080']
  backlog: 2048
  workers: 12
  worker_class: sync
  threads: 1
  worker_connections: 1000
  max_requests: 0
  max_requests_jitter: 0
  timeout: 30
  graceful_timeout: 30
  keepalive: 2
  limit_request_line: 4094
  limit_request_fields: 100
  limit_request_field_size: 8190
  reload: False
  reload_engine: auto
  reload_extra_files: []
  spew: False
  check_config: False
  preload_app: False
  sendfile: None
  reuse_port: False
  chdir: /home/qiongwei/mycode/pythonenv/virtualenv/pingpongus
  daemon: False
  raw_env: []
  pidfile: /home/qiongwei/mycode/pythonenv/virtualenv/pingpongus/app/log/gunicorn.pid
  worker_tmp_dir: None
  user: 1000
  group: 1000
  umask: 0
  initgroups: False
  tmp_upload_dir: None
  secure_scheme_headers: {'X-FORWARDED-PROTOCOL': 'ssl', 'X-FORWARDED-PROTO': 'https', 'X-FORWARDED-SSL': 'on'}
  forwarded_allow_ips: ['127.0.0.1']
  accesslog: /home/qiongwei/mycode/pythonenv/virtualenv/pingpongus/app/log/access.log
  disable_redirect_access_to_syslog: False
  access_log_format: %(h)s %(l)s %(u)s %(t)s "%(r)s" %(s)s %(b)s "%(f)s" "%(a)s"
  errorlog: /home/qiongwei/mycode/pythonenv/virtualenv/pingpongus/app/log/debug.log
  loglevel: debug
  capture_output: False
  logger_class: gunicorn.glogging.Logger
  logconfig: None
  logconfig_dict: {}
  syslog_addr: udp://localhost:514
  syslog: False
  syslog_prefix: None
  syslog_facility: user
  enable_stdio_inheritance: False
  statsd_host: None
  dogstatsd_tags: 
  statsd_prefix: 
  proc_name: None
  default_proc_name: run:app
  pythonpath: None
  paste: None
  on_starting: <function OnStarting.on_starting at 0x7f80a92f9440>
  on_reload: <function OnReload.on_reload at 0x7f80a92f9560>
  when_ready: <function WhenReady.when_ready at 0x7f80a92f9680>
  pre_fork: <function Prefork.pre_fork at 0x7f80a92f97a0>
  post_fork: <function Postfork.post_fork at 0x7f80a92f98c0>
  post_worker_init: <function PostWorkerInit.post_worker_init at 0x7f80a92f99e0>
  worker_int: <function WorkerInt.worker_int at 0x7f80a92f9b00>
  worker_abort: <function WorkerAbort.worker_abort at 0x7f80a92f9c20>
  pre_exec: <function PreExec.pre_exec at 0x7f80a92f9d40>
  pre_request: <function PreRequest.pre_request at 0x7f80a92f9e60>
  post_request: <function PostRequest.post_request at 0x7f80a92f9ef0>
  child_exit: <function ChildExit.child_exit at 0x7f80a91c8050>
  worker_exit: <function WorkerExit.worker_exit at 0x7f80a91c8170>
  nworkers_changed: <function NumWorkersChanged.nworkers_changed at 0x7f80a91c8290>
  on_exit: <function OnExit.on_exit at 0x7f80a91c83b0>
  proxy_protocol: False
  proxy_allow_ips: ['127.0.0.1']
  keyfile: None
  certfile: None
  ssl_version: 2
  cert_reqs: 0
  ca_certs: None
  suppress_ragged_eofs: True
  do_handshake_on_connect: False
  ciphers: None
  raw_paste_global_conf: []
  strip_header_spaces: False
[2020-02-05 17:44:57 +0800] [26136] [INFO] Starting gunicorn 20.0.4
[2020-02-05 17:44:57 +0800] [26136] [DEBUG] Arbiter booted
[2020-02-05 17:44:57 +0800] [26136] [INFO] Listening at: http://0.0.0.0:8080 (26136)
[2020-02-05 17:44:57 +0800] [26136] [INFO] Using worker: sync
[2020-02-05 17:44:57 +0800] [26142] [INFO] Booting worker with pid: 26142
[2020-02-05 17:44:57 +0800] [26143] [INFO] Booting worker with pid: 26143
[2020-02-05 17:44:57 +0800] [26144] [INFO] Booting worker with pid: 26144
[2020-02-05 17:44:58 +0800] [26145] [INFO] Booting worker with pid: 26145
[2020-02-05 17:44:58 +0800] [26146] [INFO] Booting worker with pid: 26146
[2020-02-05 17:44:58 +0800] [26147] [INFO] Booting worker with pid: 26147
[2020-02-05 17:44:58 +0800] [26148] [INFO] Booting worker with pid: 26148
[2020-02-05 17:44:58 +0800] [26149] [INFO] Booting worker with pid: 26149
[2020-02-05 17:44:58 +0800] [26150] [INFO] Booting worker with pid: 26150
[2020-02-05 17:44:58 +0800] [26151] [INFO] Booting worker with pid: 26151
[2020-02-05 17:44:58 +0800] [26152] [INFO] Booting worker with pid: 26152
[2020-02-05 17:44:58 +0800] [26153] [INFO] Booting worker with pid: 26153
[2020-02-05 17:44:58 +0800] [26136] [DEBUG] 12 workers
[2020-02-05 17:45:00 +0800] [26145] [DEBUG] GET /h5snake
[2020-02-05 17:45:10 +0800] [26152] [DEBUG] GET /h5snake
[2020-02-05 17:47:32 +0800] [26148] [DEBUG] GET /h5snake
[2020-02-05 17:47:47 +0800] [26148] [DEBUG] GET /h5snake
[2020-02-05 17:48:55 +0800] [26136] [INFO] Handling signal: int
[2020-02-05 17:48:55 +0800] [26151] [INFO] Worker exiting (pid: 26151)
[2020-02-05 17:48:55 +0800] [26152] [INFO] Worker exiting (pid: 26152)
[2020-02-05 17:48:55 +0800] [26142] [INFO] Worker exiting (pid: 26142)
[2020-02-05 17:48:55 +0800] [26143] [INFO] Worker exiting (pid: 26143)
[2020-02-05 17:48:55 +0800] [26148] [INFO] Worker exiting (pid: 26148)
[2020-02-05 17:48:55 +0800] [26150] [INFO] Worker exiting (pid: 26150)
[2020-02-05 17:48:55 +0800] [26153] [INFO] Worker exiting (pid: 26153)
[2020-02-05 17:48:55 +0800] [26149] [INFO] Worker exiting (pid: 26149)
[2020-02-05 17:48:55 +0800] [26144] [INFO] Worker exiting (pid: 26144)
[2020-02-05 17:48:55 +0800] [26146] [INFO] Worker exiting (pid: 26146)
[2020-02-05 17:48:55 +0800] [26145] [INFO] Worker exiting (pid: 26145)
[2020-02-05 17:48:55 +0800] [26147] [INFO] Worker exiting (pid: 26147)
[2020-02-05 17:48:55 +0800] [26136] [INFO] Shutting down: Master
